Workbook

Sheet Dashboard
A2: WOLF COLA
A3: Manufacturing Line Productivity | Q3: 29 Aug – 3 Sep 2024
D5: Line Efficiency | H5: Downtime Rate | L5: Total Downtime | P5: Downtime Events
D6: ='EDA Summary'!B1 -> 0.6402281 | H6: ='EDA Summary'!B8 -> 0.3597719 | L6: =INT('EDA Summary'!B5/60)&"h "&MOD('EDA Summary'!B5,60)&"m" -> 23h 8m | P6: =COUNTA('Fact Downtime'!A2:A62) -> 61
D7: Minimum time ÷ Actual time | H7: Downtime ÷ Actual time | L7: Across 38 production batches | P7: Recorded downtime events
H30: WHAT IS DRIVING DOWNTIME FOR EACH OPERATOR?
I32: Batch change | J32: Batch coding error | K32: Calibration error | L32: Conveyor belt jam | M32: Inventory shortage | N32: Label switch | O32: Labeling error | P32: Machine adjustment | Q32: Machine failure | R32: Other | S32: Product spill
H33: Charlie | I33: 10 | J33: 44 | K33: 24 | M33: 17 | N33: 10 | O33: 22 | P33: 118 | Q33: 85 | R33: 32 | S33: 22
H34: Dee | I34: 20 | J34: 30 | K34: 25 | L34: 17 | M34: 85 | N34: 23 | O34: 20 | P34: 79 | Q34: 36 | R34: 20 | S34: 15
H35: Dennis | J35: 24 | M35: 43 | P35: 120 | Q35: 88 | R35: 7 | S35: 20
H36: Mac | I36: 130 | J36: 47 | M36: 80 | P36: 15 | Q36: 45 | R36: 15
M38: DOWNTIME MINUTES
M40: <25 | N40: 25-49 | O40: 50-99 | P40: 100+

Sheet Line productivity
A1: Date | B1: Product | C1: Batch | D1: Operator | E1: Start Time | F1: End Time
A2: 45533 | B2: OR-600 | C2: 422111 | D2: Mac | E2: 0.49305556 | F2: 0.58680556
A3: 45533 | B3: LE-600 | C3: 422112 | D3: Mac | E3: 0.58680556 | F3: 0.65625
A4: 45533 | B4: LE-600 | C4: 422113 | D4: Mac | E4: 0.65625 | F4: 0.73263889
A5: 45533 | B5: LE-600 | C5: 422114 | D5: Mac | E5: 0.73263889 | F5: 0.80208333
A6: 45533 | B6: LE-600 | C6: 422115 | D6: Charlie | E6: 0.80208333 | F6: 0.86041667
A7: 45533 | B7: LE-600 | C7: 422116 | D7: Charlie | E7: 0.86041667 | F7: 0.90208333
A8: 45533 | B8: LE-600 | C8: 422117 | D8: Charlie | E8: 0.90208333 | F8: 0.95416667
A9: 45534 | B9: CO-600 | C9: 422118 | D9: Dee | E9: 0.17013889 | F9: 0.25347222
A10: 45534 | B10: CO-600 | C10: 422119 | D10: Dee | E10: 0.25347222 | F10: 0.3125
A11: 45534 | B11: CO-600 | C11: 422120 | D11: Dee | E11: 0.3125 | F11: 0.39027778
A12: 45534 | B12: CO-600 | C12: 422121 | D12: Dennis | E12: 0.39027778 | F12: 0.44236111
A13: 45534 | B13: CO-600 | C13: 422122 | D13: Dennis | E13: 0.44236111 | F13: 0.50138889
... A39: 45538 | B39: CO-2L | C39: 422148 | D39: Mac | E39: 0.95486111 | F39: 1.0451389

Sheet Products
A1: Product | B1: Flavor | C1: Size | D1: Min batch time
A2: OR-600 | B2: Orange | C2: 600 ml | D2: 60
A3: LE-600 | B3: Lemon lime | C3: 600 ml | D3: 60
A4: CO-600 | B4: Cola | C4: 600 ml | D4: 60
A5: DC-600 | B5: Diet Cola | C5: 600 ml | D5: 60
A6: RB-600 | B6: Root Beer | C6: 600 ml | D6: 60
A7: CO-2L | B7: Cola | C7: 2 L | D7: 98

Sheet Downtime factors
A1: Factor | B1: Description | C1: Operator Error
A2: 1 | B2: Emergency stop | C2: No
A3: 2 | B3: Batch change | C3: Yes
A4: 3 | B4: Labeling error | C4: No
A5: 4 | B5: Inventory shortage | C5: No
A6: 5 | B6: Product spill | C6: Yes
A7: 6 | B7: Machine adjustment | C7: Yes
A8: 7 | B8: Machine failure | C8: No
A9: 8 | B9: Batch coding error | C9: Yes
A10: 9 | B10: Conveyor belt jam | C10: No
A11: 10 | B11: Calibration error | C11: Yes
A12: 11 | B12: Label switch | C12: Yes
A13: 12 | B13: Other | C13: No

Sheet Line downtime
B1: Downtime factor
A2: Batch | B2: 1 | C2: 2 | D2: 3 | E2: 4 | F2: 5 | G2: 6 | H2: 7 | I2: 8 | J2: 9 | K2: 10 | L2: 11 | M2: 12
A3: 422111 | C3: 60 | H3: 15
A4: 422112 | C4: 20 | I4: 20
A5: 422113 | C5: 50
A6: 422114 | E6: 25 | G6: 15
A7: 422115 | K7: 24
A8: 422116
A9: 422117 | C9: 10 | G9: 5
A10: 422118 | G10: 14 | H10: 16 | L10: 10 | M10: 20
A11: 422119 | E11: 25
A12: 422120 | E12: 20 | F12: 15 | J12: 17
A13: 422121 | H13: 15
A14: 422122 | H14: 25
A15: 422123 | E15: 43 | H15: 30
A16: 422124 | F16: 20 | G16: 20
A17: 422125 | L17: 10 | M17: 10
A18: 422126 | I18: 44
A19: 422127 | G19: 23
A20: 422128 | F20: 22 | H20: 30
A21: 422129 | M21: 15
A22: 422130 | C22: 20
A23: 422131 | E23: 20 | K23: 10
A24: 422132
A25: 422133 | H25: 20
A26: 422134 | H26: 30 | I26: 20
A27: 422135 | E27: 30 | M27: 15
A28: 422136
A29: 422137 | I29: 30 | K29: 15
A30: 422138 | D30: 20
A31: 422139 | E31: 20 | G31: 15
A32: 422140 | G32: 50 | L32: 13
A33: 422141 | M33: 7
A34: 422142 | G34: 30
A35: 422143 | G35: 40 | H35: 18
A36: 422144 | G36: 30 | I36: 24
A37: 422145 | D37: 22
A38: 422146 | G38: 30 | H38: 25 | M38: 7
A39: 422147 | E39: 17 | G39: 60 | H39: 30
A40: 422148 | E40: 25 | I40: 7
...

Sheet Dataset Audit
A1: Line productivity
A2: Rows: | B2: 39
A3: Columns: | B3: 6
A4: Unique batches: | B4: 38
A5: Unique operators: | B5: 4
A6: Unique products: | B6: 6
A7: Date range: | B7: 29 August 2024 – 3 September 2024. Some calendar dates within this period have no recorded production batches
A8: Missing values: | B8: None
A9: Duplicate batches: | B9: Every batch has a unique value
A11: Products
A12: Rows: | B12: 7
A13: Columns: | B13: 4
A14: Unique products: | B14: 6
A15: Missing values: | B15: None
A16: Duplicate products: | B16: None
A18: Line downtime
A19: Rows: | B19: 40
A20: Columns: | B20: 13
A21: Unique batches: | B21: 38
A22: Number of downtime factors: | B22: 12
A23: Missing values: | B23: Looking at the data, i think the only time there was a recording here is when there was a downtime, by factor, so there are some blanks. Blank cells occur across the downtime-factor columns. Based on the table structure, these appear to represent factors for which no downtime was recorded for a particular batch. This interpretation will be validated before blanks are converted to zero during data cleaning. The table is currently in wide format, with 12 downtime-factor columns. Each batch can have downtime recorded across multiple factors. The data may need to be reshaped into long format for factor-level analysis.
A25: Downtime factors
A26: Rows: | B26: 13
A27: Columns: | B27: 3
A28: Number of factors: | B28: 12
A29: Operator Error values: | B29: Yes/No
A31: Data Set Understanding and Quality Checks
A32: Check | B32: Result
A33: Date/time fields recognised correctly | B33: ✅ Pass
A34: Product IDs match Products table | B34: ✅ 38/38
A35: Batch IDs match Line Downtime | B35: ✅ 38/38
A36: Downtime factors 1–12 valid | B36: ✅ Pass
A37: Operator values consistent - Four names, consistently spelled | B37: ✅ Pass
A39: There are no obvious structural integrity problems in the dataset.
A41: Source Total Downtime | B41: Fact Downtime Total
A42: =SUM('Line downtime'!B3:M40) -> 1388 | B42: =SUM('Fact Downtime'!C2:C62) -> 1388
A44: Transformation check | B44: Result
A45: 38 batches in source | B45: ✅
A46: 12 downtime factors | B46: ✅
A47: 61 recorded downtime entries | B47: ✅
...

Sheet Copy Line downtime
A1: Batch | B1: 1 | C1: 2 | D1: 3 | E1: 4 | F1: 5 | G1: 6 | H1: 7 | I1: 8 | J1: 9 | K1: 10 | L1: 11 | M1: 12
A2: 422111 | C2: 60 | H2: 15
A3: 422112 | C3: 20 | I3: 20
A4: 422113 | C4: 50
A5: 422114 | E5: 25 | G5: 15
A6: 422115 | K6: 24
A7: 422116
A8: 422117 | C8: 10 | G8: 5
A9: 422118 | G9: 14 | H9: 16 | L9: 10 | M9: 20
A10: 422119 | E10: 25
A11: 422120 | E11: 20 | F11: 15 | J11: 17
A12: 422121 | H12: 15
A13: 422122 | H13: 25
A14: 422123 | E14: 43 | H14: 30
A15: 422124 | F15: 20 | G15: 20
A16: 422125 | L16: 10 | M16: 10
A17: 422126 | I17: 44
A18: 422127 | G18: 23
A19: 422128 | F19: 22 | H19: 30
A20: 422129 | M20: 15
A21: 422130 | C21: 20
A22: 422131 | E22: 20 | K22: 10
A23: 422132
A24: 422133 | H24: 20
A25: 422134 | H25: 30 | I25: 20
A26: 422135 | E26: 30 | M26: 15
A27: 422136
A28: 422137 | I28: 30 | K28: 15
A29: 422138 | D29: 20
A30: 422139 | E30: 20 | G30: 15
A31: 422140 | G31: 50 | L31: 13
A32: 422141 | M32: 7
A33: 422142 | G33: 30
A34: 422143 | G34: 40 | H34: 18
A35: 422144 | G35: 30 | I35: 24
A36: 422145 | D36: 22
A37: 422146 | G37: 30 | H37: 25 | M37: 7
A38: 422147 | E38: 17 | G38: 60 | H38: 30
A39: 422148 | E39: 25 | I39: 7
A41: {=COUNTA(_xlfn.UNIQUE(_xlfn._xlws.FILTER(A2:A39, A2:A39 <> "")))} -> 38

Sheet Fact Downtime
A1: Batch | B1: Downtime Factor | C1: Downtime Minutes | D1: Factor Description | E1: Operator Error | F1: Operator
A2: {=_xlfn.LET( _xlpm.batch,'Copy Line downtime'!$A$2:$A$39, _xlpm.factors,'Copy Line downtime'!$B$1:$M$1, _xlpm.values,'Copy Line downtime'!$B$2:$M$39, _xlpm.n,ROWS(_xlpm.batch), _xlpm.k,COLUMNS(_xlpm.values), _xlpm.s,_xlfn.SEQUENCE(_xlpm.n*_xlpm.k), _xlpm.b,INDEX(_xlpm.batch,MOD(_xlpm.s-1,_xlpm.n)+1), _xlpm.f,--INDEX(_xlpm.factors,1,INT((_xlpm.s-1)/_xlpm.n)+1), _xlpm.v,INDEX(_xlpm.values,MOD(_xlpm.s-1,_xlpm.n)+1,INT((_xlpm.s-1)/_xlpm.n)+1), _xlfn._xlws.FILTER(_xlfn.HSTACK(_xlpm.b,_xlpm.f,_xlpm.v),_xlpm.v<>"") )} -> 422111 | B2: 2 | C2: 60 | D2: =_xlfn.XLOOKUP(B2,'Downtime factors'!$A$2:$A$13,'Downtime factors'!$B$2:$B$13,"Not Found") -> Batch change | E2: =_xlfn.XLOOKUP(B2,'Downtime factors'!$A$2:$A$13,'Downtime factors'!$C$2:$C$13,"Not Found") -> Yes | F2: =_xlfn.XLOOKUP(A2,'Line productivity'!$C$2:$C$39,'Line productivity'!$D$2:$D$39,"Not Found") -> Mac | G2: =B2='Downtime factors'!A3 -> TRUE | H2: =ISTEXT(B2) -> FALSE
A3: 422112 | B3: 2 | C3: 20 | D3: =_xlfn.XLOOKUP(B3,'Downtime factors'!$A$2:$A$13,'Downtime factors'!$B$2:$B$13,"Not Found") -> Batch change | E3: =_xlfn.XLOOKUP(B3,'Downtime factors'!$A$2:$A$13,'Downtime factors'!$C$2:$C$13,"Not Found") -> Yes | F3: =_xlfn.XLOOKUP(A3,'Line productivity'!$C$2:$C$39,'Line productivity'!$D$2:$D$39,"Not Found") -> Mac
A4: 422113 | B4: 2 | C4: 50 | D4: =_xlfn.XLOOKUP(B4,'Downtime factors'!$A$2:$A$13,'Downtime factors'!$B$2:$B$13,"Not Found") -> Batch change | E4: =_xlfn.XLOOKUP(B4,'Downtime factors'!$A$2:$A$13,'Downtime factors'!$C$2:$C$13,"Not Found") -> Yes | F4: =_xlfn.XLOOKUP(A4,'Line productivity'!$C$2:$C$39,'Line productivity'!$D$2:$D$39,"Not Found") -> Mac
A5: 422117 | B5: 2 | C5: 10 | D5: =_xlfn.XLOOKUP(B5,'Downtime factors'!$A$2:$A$13,'Downtime factors'!$B$2:$B$13,"Not Found") -> Batch change | E5: =_xlfn.XLOOKUP(B5,'Downtime factors'!$A$2:$A$13,'Downtime factors'!$C$2:$C$13,"Not Found") -> Yes | F5: =_xlfn.XLOOKUP(A5,'Line productivity'!$C$2:$C$39,'Line productivity'!$D$2:$D$39,"Not Found") -> Charlie
A6: 422130 | B6: 2 | C6: 20 | D6: =_xlfn.XLOOKUP(B6,'Downtime factors'!$A$2:$A$13,'Downtime factors'!$B$2:$B$13,"Not Found") -> Batch change | E6: =_xlfn.XLOOKUP(B6,'Downtime factors'!$A$2:$A$13,'Downtime factors'!$C$2:$C$13,"Not Found") -> Yes | F6: =_xlfn.XLOOKUP(A6,'Line productivity'!$C$2:$C$39,'Line productivity'!$D$2:$D$39,"Not Found") -> Dee
A7: 422138 | B7: 3 | C7: 20 | D7: =_xlfn.XLOOKUP(B7,'Downtime factors'!$A$2:$A$13,'Downtime factors'!$B$2:$B$13,"Not Found") -> Labeling error | E7: =_xlfn.XLOOKUP(B7,'Downtime factors'!$A$2:$A$13,'Downtime factors'!$C$2:$C$13,"Not Found") -> No | F7: =_xlfn.XLOOKUP(A7,'Line productivity'!$C$2:$C$39,'Line productivity'!$D$2:$D$39,"Not Found") -> Dee
A8: 422145 | B8: 3 | C8: 22 | D8: =_xlfn.XLOOKUP(B8,'Downtime factors'!$A$2:$A$13,'Downtime factors'!$B$2:$B$13,"Not Found") -> Labeling error | E8: =_xlfn.XLOOKUP(B8,'Downtime factors'!$A$2:$A$13,'Downtime factors'!$C$2:$C$13,"Not Found") -> No | F8: =_xlfn.XLOOKUP(A8,'Line productivity'!$C$2:$C$39,'Line productivity'!$D$2:$D$39,"Not Found") -> Charlie
A9: 422114 | B9: 4 | C9: 25 | D9: =_xlfn.XLOOKUP(B9,'Downtime factors'!$A$2:$A$13,'Downtime factors'!$B$2:$B$13,"Not Found") -> Inventory shortage | E9: =_xlfn.XLOOKUP(B9,'Downtime factors'!$A$2:$A$13,'Downtime factors'!$C$2:$C$13,"Not Found") -> No | F9: =_xlfn.XLOOKUP(A9,'Line productivity'!$C$2:$C$39,'Line productivity'!$D$2:$D$39,"Not Found") -> Mac
A10: 422119 | B10: 4 | C10: 25 | D10: =_xlfn.XLOOKUP(B10,'Downtime factors'!$A$2:$A$13,'Downtime factors'!$B$2:$B$13,"Not Found") -> Inventory shortage | E10: =_xlfn.XLOOKUP(B10,'Downtime factors'!$A$2:$A$13,'Downtime factors'!$C$2:$C$13,"Not Found") -> No | F10: =_xlfn.XLOOKUP(A10,'Line productivity'!$C$2:$C$39,'Line productivity'!$D$2:$D$39,"Not Found") -> Dee
A11: 422120 | B11: 4 | C11: 20 | D11: =_xlfn.XLOOKUP(B11,'Downtime factors'!$A$2:$A$13,'Downtime factors'!$B$2:$B$13,"Not Found") -> Inventory shortage | E11: =_xlfn.XLOOKUP(B11,'Downtime factors'!$A$2:$A$13,'Downtime factors'!$C$2:$C$13,"Not Found") -> No | F11: =_xlfn.XLOOKUP(A11,'Line productivity'!$C$2:$C$39,'Line productivity'!$D$2:$D$39,"Not Found") -> Dee
A12: 422123 | B12: 4 | C12: 43 | D12: =_xlfn.XLOOKUP(B12,'Downtime factors'!$A$2:$A$13,'Downtime factors'!$B$2:$B$13,"Not Found") -> Inventory shortage | E12: =_xlfn.XLOOKUP(B12,'Downtime factors'!$A$2:$A$13,'Downtime factors'!$C$2:$C$13,"Not Found") -> No | F12: =_xlfn.XLOOKUP(A12,'Line productivity'!$C$2:$C$39,'Line productivity'!$D$2:$D$39,"Not Found") -> Dennis
A13: 422131 | B13: 4 | C13: 20 | D13: =_xlfn.XLOOKUP(B13,'Downtime factors'!$A$2:$A$13,'Downtime factors'!$B$2:$B$13,"Not Found") -> Inventory shortage | E13: =_xlfn.XLOOKUP(B13,'Downtime factors'!$A$2:$A$13,'Downtime factors'!$C$2:$C$13,"Not Found") -> No | F13: =_xlfn.XLOOKUP(A13,'Line productivity'!$C$2:$C$39,'Line productivity'!$D$2:$D$39,"Not Found") -> Dee
A14: 422135 | B14: 4 | C14: 30 | D14: =_xlfn.XLOOKUP(B14,'Downtime factors'!$A$2:$A$13,'Downtime factors'!$B$2:$B$13,"Not Found") -> Inventory shortage | E14: =_xlfn.XLOOKUP(B14,'Downtime factors'!$A$2:$A$13,'Downtime factors'!$C$2:$C$13,"Not Found") -> No | F14: =_xlfn.XLOOKUP(A14,'Line productivity'!$C$2:$C$39,'Line productivity'!$D$2:$D$39,"Not Found") -> Mac
... A62: 422146 | B62: 12 | C62: 7 | D62: =_xlfn.XLOOKUP(B62,'Downtime factors'!$A$2:$A$13,'Downtime factors'!$B$2:$B$13,"Not Found") -> Other | E62: =_xlfn.XLOOKUP(B62,'Downtime factors'!$A$2:$A$13,'Downtime factors'!$C$2:$C$13,"Not Found") -> No | F62: =_xlfn.XLOOKUP(A62,'Line productivity'!$C$2:$C$39,'Line productivity'!$D$2:$D$39,"Not Found") -> Charlie

Sheet Production Analysis
A1: Batch | B1: Date | C1: Product | D1: Operator | E1: Start Time | F1: End Time | G1: Min Batch Time | H1: Actual Batch Time | I1: Time Above Min | J1: Recorded Downtime Minutes | K1: Unexplained/Other time | L1: Efficiency% | M1: Downtime%
A2: ='Line productivity'!C2 -> 422111 | B2: ='Line productivity'!A2 -> 45533 | C2: ='Line productivity'!B2 -> OR-600 | D2: ='Line productivity'!D2 -> Mac | E2: ='Line productivity'!E2 -> 0.49305556 | F2: ='Line productivity'!F2 -> 0.58680556 | G2: =_xlfn.XLOOKUP(C2,Products!$A$2:$A$7,Products!$D$2:$D$7,"Not Found") -> 60 | H2: =(F2-E2)*1440 -> 135 | I2: =H2-G2 -> 75 | J2: =SUMIF('Fact Downtime'!$A:$A,A2,'Fact Downtime'!$C:$C) -> 75 | K2: =I2-J2 -> 0 | L2: =G2/H2 -> 0.44444444 | M2: =J2/H2 -> 0.55555556
A3: ='Line productivity'!C3 -> 422112 | B3: ='Line productivity'!A3 -> 45533 | C3: ='Line productivity'!B3 -> LE-600 | D3: ='Line productivity'!D3 -> Mac | E3: ='Line productivity'!E3 -> 0.58680556 | F3: ='Line productivity'!F3 -> 0.65625 | G3: =_xlfn.XLOOKUP(C3,Products!$A$2:$A$7,Products!$D$2:$D$7,"Not Found") -> 60 | H3: =(F3-E3)*1440 -> 100 | I3: =H3-G3 -> 40 | J3: =SUMIF('Fact Downtime'!$A:$A,A3,'Fact Downtime'!$C:$C) -> 40 | K3: =I3-J3 -> 0 | L3: =G3/H3 -> 0.6 | M3: =J3/H3 -> 0.4
A4: ='Line productivity'!C4 -> 422113 | B4: ='Line productivity'!A4 -> 45533 | C4: ='Line productivity'!B4 -> LE-600 | D4: ='Line productivity'!D4 -> Mac | E4: ='Line productivity'!E4 -> 0.65625 | F4: ='Line productivity'!F4 -> 0.73263889 | G4: =_xlfn.XLOOKUP(C4,Products!$A$2:$A$7,Products!$D$2:$D$7,"Not Found") -> 60 | H4: =(F4-E4)*1440 -> 110 | I4: =H4-G4 -> 50 | J4: =SUMIF('Fact Downtime'!$A:$A,A4,'Fact Downtime'!$C:$C) -> 50 | K4: =I4-J4 -> -7.1054274e-14 | L4: =G4/H4 -> 0.54545455 | M4: =J4/H4 -> 0.45454545
A5: ='Line productivity'!C5 -> 422114 | B5: ='Line productivity'!A5 -> 45533 | C5: ='Line productivity'!B5 -> LE-600 | D5: ='Line productivity'!D5 -> Mac | E5: ='Line productivity'!E5 -> 0.73263889 | F5: ='Line productivity'!F5 -> 0.80208333 | G5: =_xlfn.XLOOKUP(C5,Products!$A$2:$A$7,Products!$D$2:$D$7,"Not Found") -> 60 | H5: =(F5-E5)*1440 -> 100 | I5: =H5-G5 -> 40 | J5: =SUMIF('Fact Downtime'!$A:$A,A5,'Fact Downtime'!$C:$C) -> 40 | K5: =I5-J5 -> 0 | L5: =G5/H5 -> 0.6 | M5: =J5/H5 -> 0.4
A6: ='Line productivity'!C6 -> 422115 | B6: ='Line productivity'!A6 -> 45533 | C6: ='Line productivity'!B6 -> LE-600 | D6: ='Line productivity'!D6 -> Charlie | E6: ='Line productivity'!E6 -> 0.80208333 | F6: ='Line productivity'!F6 -> 0.86041667 | G6: =_xlfn.XLOOKUP(C6,Products!$A$2:$A$7,Products!$D$2:$D$7,"Not Found") -> 60 | H6: =(F6-E6)*1440 -> 84 | I6: =H6-G6 -> 24 | J6: =SUMIF('Fact Downtime'!$A:$A,A6,'Fact Downtime'!$C:$C) -> 24 | K6: =I6-J6 -> 2.8421709e-14 | L6: =G6/H6 -> 0.71428571 | M6: =J6/H6 -> 0.28571429
A7: ='Line productivity'!C7 -> 422116 | B7: ='Line productivity'!A7 -> 45533 | C7: ='Line productivity'!B7 -> LE-600 | D7: ='Line productivity'!D7 -> Charlie | E7: ='Line productivity'!E7 -> 0.86041667 | F7: ='Line productivity'!F7 -> 0.90208333 | G7: =_xlfn.XLOOKUP(C7,Products!$A$2:$A$7,Products!$D$2:$D$7,"Not Found") -> 60 | H7: =(F7-E7)*1440 -> 60 | I7: =H7-G7 -> -5.6843419e-14 | J7: =SUMIF('Fact Downtime'!$A:$A,A7,'Fact Downtime'!$C:$C) -> 0 | K7: =I7-J7 -> -5.6843419e-14 | L7: =G7/H7 -> 1 | M7: =J7/H7 -> 0
A8: ='Line productivity'!C8 -> 422117 | B8: ='Line productivity'!A8 -> 45533 | C8: ='Line productivity'!B8 -> LE-600 | D8: ='Line productivity'!D8 -> Charlie | E8: ='Line productivity'!E8 -> 0.90208333 | F8: ='Line productivity'!F8 -> 0.95416667 | G8: =_xlfn.XLOOKUP(C8,Products!$A$2:$A$7,Products!$D$2:$D$7,"Not Found") -> 60 | H8: =(F8-E8)*1440 -> 75 | I8: =H8-G8 -> 15 | J8: =SUMIF('Fact Downtime'!$A:$A,A8,'Fact Downtime'!$C:$C) -> 15 | K8: =I8-J8 -> 5.6843419e-14 | L8: =G8/H8 -> 0.8 | M8: =J8/H8 -> 0.2
A9: ='Line productivity'!C9 -> 422118 | B9: ='Line productivity'!A9 -> 45534 | C9: ='Line productivity'!B9 -> CO-600 | D9: ='Line productivity'!D9 -> Dee | E9: ='Line productivity'!E9 -> 0.17013889 | F9: ='Line productivity'!F9 -> 0.25347222 | G9: =_xlfn.XLOOKUP(C9,Products!$A$2:$A$7,Products!$D$2:$D$7,"Not Found") -> 60 | H9: =(F9-E9)*1440 -> 120 | I9: =H9-G9 -> 60 | J9: =SUMIF('Fact Downtime'!$A:$A,A9,'Fact Downtime'!$C:$C) -> 60 | K9: =I9-J9 -> 0 | L9: =G9/H9 -> 0.5 | M9: =J9/H9 -> 0.5
A10: ='Line productivity'!C10 -> 422119 | B10: ='Line productivity'!A10 -> 45534 | C10: ='Line productivity'!B10 -> CO-600 | D10: ='Line productivity'!D10 -> Dee | E10: ='Line productivity'!E10 -> 0.25347222 | F10: ='Line productivity'!F10 -> 0.3125 | G10: =_xlfn.XLOOKUP(C10,Products!$A$2:$A$7,Products!$D$2:$D$7,"Not Found") -> 60 | H10: =(F10-E10)*1440 -> 85 | I10: =H10-G10 -> 25 | J10: =SUMIF('Fact Downtime'!$A:$A,A10,'Fact Downtime'!$C:$C) -> 25 | K10: =I10-J10 -> 0 | L10: =G10/H10 -> 0.70588235 | M10: =J10/H10 -> 0.29411765
A11: ='Line productivity'!C11 -> 422120 | B11: ='Line productivity'!A11 -> 45534 | C11: ='Line productivity'!B11 -> CO-600 | D11: ='Line productivity'!D11 -> Dee | E11: ='Line productivity'!E11 -> 0.3125 | F11: ='Line productivity'!F11 -> 0.39027778 | G11: =_xlfn.XLOOKUP(C11,Products!$A$2:$A$7,Products!$D$2:$D$7,"Not Found") -> 60 | H11: =(F11-E11)*1440 -> 112 | I11: =H11-G11 -> 52 | J11: =SUMIF('Fact Downtime'!$A:$A,A11,'Fact Downtime'!$C:$C) -> 52 | K11: =I11-J11 -> 0 | L11: =G11/H11 -> 0.53571429 | M11: =J11/H11 -> 0.46428571
A12: ='Line productivity'!C12 -> 422121 | B12: ='Line productivity'!A12 -> 45534 | C12: ='Line productivity'!B12 -> CO-600 | D12: ='Line productivity'!D12 -> Dennis | E12: ='Line productivity'!E12 -> 0.39027778 | F12: ='Line productivity'!F12 -> 0.44236111 | G12: =_xlfn.XLOOKUP(C12,Products!$A$2:$A$7,Products!$D$2:$D$7,"Not Found") -> 60 | H12: =(F12-E12)*1440 -> 75 | I12: =H12-G12 -> 15 | J12: =SUMIF('Fact Downtime'!$A:$A,A12,'Fact Downtime'!$C:$C) -> 15 | K12: =I12-J12 -> -2.8421709e-14 | L12: =G12/H12 -> 0.8 | M12: =J12/H12 -> 0.2
A13: ='Line productivity'!C13 -> 422122 | B13: ='Line productivity'!A13 -> 45534 | C13: ='Line productivity'!B13 -> CO-600 | D13: ='Line productivity'!D13 -> Dennis | E13: ='Line productivity'!E13 -> 0.44236111 | F13: ='Line productivity'!F13 -> 0.50138889 | G13: =_xlfn.XLOOKUP(C13,Products!$A$2:$A$7,Products!$D$2:$D$7,"Not Found") -> 60 | H13: =(F13-E13)*1440 -> 85 | I13: =H13-G13 -> 25 | J13: =SUMIF('Fact Downtime'!$A:$A,A13,'Fact Downtime'!$C:$C) -> 25 | K13: =I13-J13 -> 0 | L13: =G13/H13 -> 0.70588235 | M13: =J13/H13 -> 0.29411765
... A39: ='Line productivity'!C39 -> 422148 | B39: ='Line productivity'!A39 -> 45538 | C39: ='Line productivity'!B39 -> CO-2L | D39: ='Line productivity'!D39 -> Mac | E39: ='Line productivity'!E39 -> 0.95486111 | F39: ='Line productivity'!F39 -> 1.0451389 | G39: =_xlfn.XLOOKUP(C39,Products!$A$2:$A$7,Products!$D$2:$D$7,"Not Found") -> 98 | H39: =(F39-E39)*1440 -> 130 | I39: =H39-G39 -> 32 | J39: =SUMIF('Fact Downtime'!$A:$A,A39,'Fact Downtime'!$C:$C) -> 32 | K39: =I39-J39 -> -1.4210855e-13 | L39: =G39/H39 -> 0.75384615 | M39: =J39/H39 -> 0.24615385
H41: =MAX(H2:H39) -> 205 | I41: =SUM(I2:I39) -> 1388 | J41: =SUM(J2:J39) -> 1388 | L41: =AVERAGE(L2:L39) -> 0.67076697
H42: =MIN(H2:H39) -> 60 | I42: =MIN(I2:I39) -> -5.6843419e-14 | J42: =MIN(J2:J39) -> 0
I43: =MAX(I2:I39) -> 107 | J43: =MAX(J2:J39) -> 107

Sheet EDA Downtime
A3: Factor Description | B3: Sum of Downtime Minutes
A4: Machine adjustment | B4: 332
A5: Machine failure | B5: 254
A6: Inventory shortage | B6: 225
A7: Batch change | B7: 160
A8: Batch coding error | B8: 145
A9: Other | B9: 74
A10: Product spill | B10: 57
A11: Calibration error | B11: 49
A12: Labeling error | B12: 42
A13: Label switch | B13: 33
A14: Conveyor belt jam | B14: 17
A15: Grand Total | B15: 1388
A19: Operator Error | B19: Sum of Downtime Minutes | C19: Sum of Downtime Minutes2 | D19: Count of Downtime Factor | E19: Average of Downtime Minutes3
A20: No | B20: 612 | C20: 0.44092219 | D20: 29 | E20: 21.103448
A21: Yes | B21: 776 | C21: 0.55907781 | D21: 32 | E21: 24.25
A22: Grand Total | B22: 1388 | C22: 1 | D22: 61 | E22: 22.754098
A25: Which specific downtime factors are driving the 55.91% operator-related downtime?
A26: Sum of Downtime Minutes | B26: Operator Error
A27: Factor Description | B27: Yes | C27: No | D27: Grand Total
A28: Machine adjustment | B28: 332 | D28: 332
A29: Machine failure | C29: 254 | D29: 254
A30: Inventory shortage | C30: 225 | D30: 225
A31: Batch change | B31: 160 | D31: 160
A32: Batch coding error | B32: 145 | D32: 145
A33: Other | C33: 74 | D33: 74
A34: Product spill | B34: 57 | D34: 57
A35: Calibration error | B35: 49 | D35: 49
A36: Labeling error | C36: 42 | D36: 42
A37: Label switch | B37: 33 | D37: 33
A38: Conveyor belt jam | C38: 17 | D38: 17
A39: Grand Total | B39: 776 | C39: 612 | D39: 1388

Sheet EDA Operator Perfomance
A3: Operator | B3: Count of Batch | C3: Sum of Actual Batch Time | D3: Sum of Recorded Downtime Minutes | E3: Downtime %
A4: Charlie | B4: 11 | C4: 1158 | D4: 384 | E4: =D4/C4 -> 0.33160622
A5: Dee | B5: 11 | C5: 1030 | D5: 370 | E5: =D5/C5 -> 0.3592233
A6: Dennis | B6: 8 | C6: 820 | D6: 302 | E6: =D6/C6 -> 0.36829268
A7: Mac | B7: 8 | C7: 850 | D7: 332 | E7: =D7/C7 -> 0.39058824
A8: Grand Total | B8: 38 | C8: 3858 | D8: 1388
A13: Sum of Downtime Minutes | B13: Factor Description
A14: Operator | B14: Batch change | C14: Batch coding error | D14: Calibration error | E14: Conveyor belt jam | F14: Inventory shortage | G14: Label switch | H14: Labeling error | I14: Machine adjustment | J14: Machine failure | K14: Other | L14: Product spill | M14: Grand Total
A15: Charlie | B15: 10 | C15: 44 | D15: 24 | F15: 17 | G15: 10 | H15: 22 | I15: 118 | J15: 85 | K15: 32 | L15: 22 | M15: 384
A16: Dee | B16: 20 | C16: 30 | D16: 25 | E16: 17 | F16: 85 | G16: 23 | H16: 20 | I16: 79 | J16: 36 | K16: 20 | L16: 15 | M16: 370
A17: Dennis | C17: 24 | F17: 43 | I17: 120 | J17: 88 | K17: 7 | L17: 20 | M17: 302
A18: Mac | B18: 130 | C18: 47 | F18: 80 | I18: 15 | J18: 45 | K18: 15 | M18: 332
A19: Grand Total | B19: 160 | C19: 145 | D19: 49 | E19: 17 | F19: 225 | G19: 33 | H19: 42 | I19: 332 | J19: 254 | K19: 74 | L19: 57 | M19: 1388
A21: Mac has the highest downtime rate, but his downtime pattern is different from the other operators.

Sheet EDA Product Performance
A1: Are certain products associated with higher production inefficiency or downtime?
A3: Product | B3: Count of Batch | C3: Sum of Actual Batch Time | D3: Sum of Min Batch Time | E3: Sum of Recorded Downtime Minutes | F3: Downtime% | G3: Efficiency%
A4: CO-2L | B4: 5 | C4: 767 | D4: 490 | E4: 277 | F4: =E4/C4 -> 0.36114733 | G4: =D4/C4 -> 0.63885267
A5: CO-600 | B5: 15 | C5: 1394 | D5: 900 | E5: 494 | F5: =E5/C5 -> 0.3543759 | G5: =D5/C5 -> 0.6456241
A6: DC-600 | B6: 4 | C6: 355 | D6: 240 | E6: 115 | F6: =E6/C6 -> 0.32394366 | G6: =D6/C6 -> 0.67605634
A7: LE-600 | B7: 6 | C7: 529 | D7: 360 | E7: 169 | F7: =E7/C7 -> 0.3194707 | G7: =D7/C7 -> 0.6805293
A8: OR-600 | B8: 1 | C8: 135 | D8: 60 | E8: 75 | F8: =E8/C8 -> 0.55555556 | G8: =D8/C8 -> 0.44444444
A9: RB-600 | B9: 7 | C9: 678 | D9: 420 | E9: 258 | F9: =E9/C9 -> 0.38053097 | G9: =D9/C9 -> 0.61946903
A10: Grand Total | B10: 38 | C10: 3858 | D10: 2470 | E10: 1388
A12: OR-600 shows the lowest observed efficiency and highest downtime rate, but this is based on a single batch and therefore is insufficient evidence of a systematic product-level issue.

Sheet EDA Time
A1: Is efficiency/downtime getting better or worse over time?
A3: Date | B3: Count of Batch | C3: Sum of Actual Batch Time | D3: Sum of Min Batch Time | E3: Sum of Recorded Downtime Minutes | F3: Downtime% | G3: Efficiency%
A4: 45533 | B4: 7 | C4: 664 | D4: 420 | E4: 244 | F4: =D4/C4 -> 0.63253012 | G4: =D4/C4 -> 0.63253012
A5: 45534 | B5: 12 | C5: 1164 | D5: 720 | E5: 444 | F5: =D5/C5 -> 0.6185567 | G5: =D5/C5 -> 0.6185567
A6: 45535 | B6: 7 | C6: 585 | D6: 420 | E6: 165 | F6: =D6/C6 -> 0.71794872 | G6: =D6/C6 -> 0.71794872
A7: 45537 | B7: 11 | C7: 1315 | D7: 812 | E7: 503 | F7: =D7/C7 -> 0.61749049 | G7: =D7/C7 -> 0.61749049
A8: 45538 | B8: 1 | C8: 130 | D8: 98 | E8: 32 | F8: =D8/C8 -> 0.75384615 | G8: =D8/C8 -> 0.75384615
A9: Grand Total | B9: 38 | C9: 3858 | D9: 2470 | E9: 1388
A11: "Efficiency fluctuated across the observed production dates, with the lowest performance occurring on 2 September."

Sheet EDA Summary
A1: Overall efficiency | B1: =B2/B3 -> 0.6402281 | C1: =SUM('Production Analysis'!G2:G39)/SUM('Production Analysis'!H2:H39) -> 0.6402281
A2: Total Minimum Batch Time | B2: =SUM('Production Analysis'!G2:G39) -> 2470
A3: Total Actual Batch Time | B3: =SUM('Production Analysis'!H2:H39) -> 3858
A5: Total Recorded Downtime | B5: =SUM('Production Analysis'!J2:J39) -> 1388
A6: Average Batch Efficiency | B6: =AVERAGE('Production Analysis'!L2:L39) -> 0.67076697 | C6: =AVERAGE('Production Analysis'!L2:L39) -> 0.67076697
A8: Overall downtime % | B8: =SUM('Production Analysis'!J2:J39)/SUM('Production Analysis'!H2:H39) -> 0.3597719 | C8: =B5/B3 -> 0.3597719
A9: Number of batches | B9: 38
A11: Operator | B11: Downtime %
A12: Mac | B12: 0.3906
A13: Dennis | B13: 0.3683
A14: Dee | B14: 0.3592
A15: Charlie | B15: 0.3316
A17: {='EDA Time'!A3:A8} -> Date | B17: Date | C17: {='EDA Time'!G3:G8} -> Efficiency%
A18: 45533 | B18: =TEXT(A18,"m/d/yyyy") -> 8/29/2024 | C18: 0.63253012
A19: 45534 | B19: =TEXT(A19,"m/d/yyyy") -> 8/30/2024 | C19: 0.6185567
A20: 45535 | B20: =TEXT(A20,"m/d/yyyy") -> 8/31/2024 | C20: 0.71794872
A21: 45537 | B21: =TEXT(A21,"m/d/yyyy") -> 9/2/2024 | C21: 0.61749049
A22: 45538 | B22: =TEXT(A22,"m/d/yyyy") -> 9/3/2024 | C22: 0.75384615
A25: {='EDA Product Performance'!A3:A9} -> Product | B25: {='EDA Product Performance'!G3:G9} -> Efficiency% | C25: {='EDA Product Performance'!F3:F9} -> Downtime%
A26: CO-2L | B26: 0.63885267 | C26: 0.36114733
A27: CO-600 | B27: 0.6456241 | C27: 0.3543759
A28: DC-600 | B28: 0.67605634 | C28: 0.32394366
A29: LE-600 | B29: 0.6805293 | C29: 0.3194707
A30: OR-600 | B30: 0.44444444 | C30: 0.55555556
A31: RB-600 | B31: 0.61946903 | C31: 0.38053097
A34: Product | B34: Downtime% | C34: Efficiency%
A35: LE-600 | B35: 0.3194707 | C35: 0.6805293 | D35: 0.3194707
A36: DC-600 | B36: 0.32394366 | C36: 0.67605634 | D36: 0.32394366
A37: CO-600 | B37: 0.3543759 | C37: 0.6456241 | D37: 0.3543759
A38: CO-2L | B38: 0.36114733 | C38: 0.63885267 | D38: 0.36114733
A39: RB-600 | B39: 0.38053097 | C39: 0.61946903 | D39: 0.38053097
A40: OR-600 | B40: 0.55555556 | C40: 0.44444444 | D40: 0.55555556
